ERROR 2022-02-23 21:05:45,655 bot_handler 156248 140016728921856 Creating bot failed because position with symbol BTC/USDT is duplicate!
ERROR 2022-02-23 21:05:56,669 bot_handler 156248 140016728921856 Creating bot failed because position with symbol BTC/USDT is duplicate!
ERROR 2022-02-23 21:15:20,161 bot_handler 156519 140311674218240 Creating bot failed because position with symbol BTC/USDT is duplicate!
ERROR 2022-02-23 21:15:41,029 retry_on_timeout 156519 140312213780224 HTTPSConnectionPool(host='api-futures.kucoin.com', port=443): Read timed out. (read timeout=5)
Traceback (most recent call last):
  File "/home/mohammad/others/codes/intellichange/DJANGO-algorithmic_trading/venv/lib/python3.8/site-packages/urllib3/connectionpool.py", line 449, in _make_request
    six.raise_from(e, None)
  File "<string>", line 3, in raise_from
  File "/home/mohammad/others/codes/intellichange/DJANGO-algorithmic_trading/venv/lib/python3.8/site-packages/urllib3/connectionpool.py", line 444, in _make_request
    httplib_response = conn.getresponse()
  File "/usr/lib/python3.8/http/client.py", line 1348, in getresponse
    response.begin()
  File "/usr/lib/python3.8/http/client.py", line 316, in begin
    version, status, reason = self._read_status()
  File "/usr/lib/python3.8/http/client.py", line 277, in _read_status
    line = str(self.fp.readline(_MAXLINE + 1), "iso-8859-1")
  File "/usr/lib/python3.8/socket.py", line 669, in readinto
    return self._sock.recv_into(b)
  File "/usr/lib/python3.8/ssl.py", line 1241, in recv_into
    return self.read(nbytes, buffer)
  File "/usr/lib/python3.8/ssl.py", line 1099, in read
    return self._sslobj.read(len, buffer)
socket.timeout: The read operation timed out

During handling of the above exception, another exception occurred:

Traceback (most recent call last):
  File "/home/mohammad/others/codes/intellichange/DJANGO-algorithmic_trading/venv/lib/python3.8/site-packages/requests/adapters.py", line 439, in send
    resp = conn.urlopen(
  File "/home/mohammad/others/codes/intellichange/DJANGO-algorithmic_trading/venv/lib/python3.8/site-packages/urllib3/connectionpool.py", line 785, in urlopen
    retries = retries.increment(
  File "/home/mohammad/others/codes/intellichange/DJANGO-algorithmic_trading/venv/lib/python3.8/site-packages/urllib3/util/retry.py", line 550, in increment
    raise six.reraise(type(error), error, _stacktrace)
  File "/home/mohammad/others/codes/intellichange/DJANGO-algorithmic_trading/venv/lib/python3.8/site-packages/urllib3/packages/six.py", line 770, in reraise
    raise value
  File "/home/mohammad/others/codes/intellichange/DJANGO-algorithmic_trading/venv/lib/python3.8/site-packages/urllib3/connectionpool.py", line 703, in urlopen
    httplib_response = self._make_request(
  File "/home/mohammad/others/codes/intellichange/DJANGO-algorithmic_trading/venv/lib/python3.8/site-packages/urllib3/connectionpool.py", line 451, in _make_request
    self._raise_timeout(err=e, url=url, timeout_value=read_timeout)
  File "/home/mohammad/others/codes/intellichange/DJANGO-algorithmic_trading/venv/lib/python3.8/site-packages/urllib3/connectionpool.py", line 340, in _raise_timeout
    raise ReadTimeoutError(
urllib3.exceptions.ReadTimeoutError: HTTPSConnectionPool(host='api-futures.kucoin.com', port=443): Read timed out. (read timeout=5)

During handling of the above exception, another exception occurred:

Traceback (most recent call last):
  File "/home/mohammad/others/codes/intellichange/DJANGO-algorithmic_trading/global_utils/retry_on_timeout.py", line 17, in caught_func
    _result, _error = func(*args, **kwargs), False
  File "/home/mohammad/others/codes/intellichange/DJANGO-algorithmic_trading/futures_trader/exchange/exchange.py", line 69, in get_all_positions
    return self._sdk_exchange.trade_client.get_all_position()
  File "/home/mohammad/others/codes/intellichange/DJANGO-algorithmic_trading/venv/lib/python3.8/site-packages/kucoin_futures/trade/trade.py", line 157, in get_all_position
    return self._request('GET', '/api/v1/positions')
  File "/home/mohammad/others/codes/intellichange/DJANGO-algorithmic_trading/venv/lib/python3.8/site-packages/kucoin_futures/base_request/base_request.py", line 87, in _request
    response_data = requests.request(method, url, headers=headers, timeout=timeout)
  File "/home/mohammad/others/codes/intellichange/DJANGO-algorithmic_trading/venv/lib/python3.8/site-packages/requests/api.py", line 61, in request
    return session.request(method=method, url=url, **kwargs)
  File "/home/mohammad/others/codes/intellichange/DJANGO-algorithmic_trading/venv/lib/python3.8/site-packages/requests/sessions.py", line 542, in request
    resp = self.send(prep, **send_kwargs)
  File "/home/mohammad/others/codes/intellichange/DJANGO-algorithmic_trading/venv/lib/python3.8/site-packages/requests/sessions.py", line 655, in send
    r = adapter.send(request, **kwargs)
  File "/home/mohammad/others/codes/intellichange/DJANGO-algorithmic_trading/venv/lib/python3.8/site-packages/requests/adapters.py", line 529, in send
    raise ReadTimeout(e, request=request)
requests.exceptions.ReadTimeout: HTTPSConnectionPool(host='api-futures.kucoin.com', port=443): Read timed out. (read timeout=5)
ERROR 2022-02-23 21:46:04,424 bot_handler 157276 139950821046016 Creating bot failed because position with symbol BTC/USDT is duplicate!
ERROR 2022-02-23 21:49:14,879 bot_handler 157383 140546455922432 Creating bot failed because position with symbol BTC/USDT is duplicate!
ERROR 2022-02-23 21:50:37,959 bot_handler 157451 140534364714752 Creating bot failed because position with symbol BTC/USDT is duplicate!
ERROR 2022-02-23 21:50:47,973 bot_handler 157451 140534364714752 Creating bot failed because position with symbol BTC/USDT is duplicate!
ERROR 2022-02-23 21:50:58,988 bot_handler 157451 140534364714752 Creating bot failed because position with symbol BTC/USDT is duplicate!
ERROR 2022-02-23 21:53:54,546 bot_handler 157604 139715075835648 Creating bot failed because position with symbol BTC/USDT is duplicate!
ERROR 2022-02-23 21:54:04,561 bot_handler 157604 139715075835648 Creating bot failed because position with symbol BTC/USDT is duplicate!
ERROR 2022-02-23 21:54:15,575 bot_handler 157604 139715075835648 Creating bot failed because position with symbol BTC/USDT is duplicate!
ERROR 2022-02-23 21:55:50,132 bot_handler 157685 140394360731392 Creating bot failed because position with symbol BTC/USDT is duplicate!
ERROR 2022-02-23 21:56:01,145 bot_handler 157685 140394360731392 Creating bot failed because position with symbol BTC/USDT is duplicate!
