ERROR 2022-08-07 19:10:10,206 catch_all_exceptions 157468 140658139170624 func=<function cancel_remaining_orders at 0x7fed7d80e040> args=() kwargs={} message=name 'self' is not defined traceback=Traceback (most recent call last):
  File "/home/mohammad/others/codes/intellichange/DJANGO-algorithmic_trading/global_utils/catch_all_exceptions.py", line 11, in wrapper
    return func(*args, **kwargs)
  File "/home/mohammad/others/codes/intellichange/DJANGO-algorithmic_trading/futures_trader/tasks.py", line 116, in cancel_remaining_orders
    active_bots = self.reload_bots()
NameError: name 'self' is not defined

ERROR 2022-08-07 19:11:00,058 catch_all_exceptions 157468 140658139170624 func=<function cancel_remaining_orders at 0x7fed7d80e040> args=() kwargs={} message=name 'self' is not defined traceback=Traceback (most recent call last):
  File "/home/mohammad/others/codes/intellichange/DJANGO-algorithmic_trading/global_utils/catch_all_exceptions.py", line 11, in wrapper
    return func(*args, **kwargs)
  File "/home/mohammad/others/codes/intellichange/DJANGO-algorithmic_trading/futures_trader/tasks.py", line 116, in cancel_remaining_orders
    active_bots = self.reload_bots()
NameError: name 'self' is not defined

ERROR 2022-08-07 19:12:00,049 catch_all_exceptions 157468 140658139170624 func=<function cancel_remaining_orders at 0x7fed7d80e040> args=() kwargs={} message=name 'self' is not defined traceback=Traceback (most recent call last):
  File "/home/mohammad/others/codes/intellichange/DJANGO-algorithmic_trading/global_utils/catch_all_exceptions.py", line 11, in wrapper
    return func(*args, **kwargs)
  File "/home/mohammad/others/codes/intellichange/DJANGO-algorithmic_trading/futures_trader/tasks.py", line 116, in cancel_remaining_orders
    active_bots = self.reload_bots()
NameError: name 'self' is not defined

ERROR 2022-08-07 19:25:38,069 catch_all_exceptions 157694 140416638281536 func=<function auto_trader_per_symbol at 0x7fb542649d30> args=('COMP/USDT', ['COMP/USDT'], []) kwargs={} message='FuturesBot' object has no attribute 'is_risky' traceback=Traceback (most recent call last):
  File "/home/mohammad/others/codes/intellichange/DJANGO-algorithmic_trading/global_utils/catch_all_exceptions.py", line 11, in wrapper
    return func(*args, **kwargs)
  File "/home/mohammad/others/codes/intellichange/DJANGO-algorithmic_trading/futures_trader/tasks.py", line 111, in auto_trader_per_symbol
    FuturesBotTrader.create_bot(bot_data)
  File "/home/mohammad/others/codes/intellichange/DJANGO-algorithmic_trading/futures_trader/services/trader.py", line 27, in create_bot
    return bot_handler.create_bot(exchange_id=bot_data['exchange_id'],
  File "/home/mohammad/others/codes/intellichange/DJANGO-algorithmic_trading/futures_trader/services/bot_handler.py", line 50, in create_bot
    if self.validate_bot_data(exchange_id, credential_id, position_data['signal']['symbol']):
  File "/home/mohammad/others/codes/intellichange/DJANGO-algorithmic_trading/futures_trader/services/bot_handler.py", line 578, in validate_bot_data
    return all([self.validate_risky_bots_limit(credential_id),
  File "/home/mohammad/others/codes/intellichange/DJANGO-algorithmic_trading/futures_trader/services/bot_handler.py", line 583, in validate_risky_bots_limit
    if not self.get_number_of_risky_bots(credential_id) < max_number_of_risky_bots:
  File "/home/mohammad/others/codes/intellichange/DJANGO-algorithmic_trading/futures_trader/services/bot_handler.py", line 575, in get_number_of_risky_bots
    return len([bot for bot in active_bots if bot.is_risky()])
  File "/home/mohammad/others/codes/intellichange/DJANGO-algorithmic_trading/futures_trader/services/bot_handler.py", line 575, in <listcomp>
    return len([bot for bot in active_bots if bot.is_risky()])
AttributeError: 'FuturesBot' object has no attribute 'is_risky'

ERROR 2022-08-07 19:28:44,230 catch_all_exceptions 157694 140416638281536 func=<function auto_trader_per_symbol at 0x7fb542649d30> args=('VET/USDT', ['COMP/USDT'], ['VET/USDT']) kwargs={} message='FuturesBot' object has no attribute 'is_risky' traceback=Traceback (most recent call last):
  File "/home/mohammad/others/codes/intellichange/DJANGO-algorithmic_trading/global_utils/catch_all_exceptions.py", line 11, in wrapper
    return func(*args, **kwargs)
  File "/home/mohammad/others/codes/intellichange/DJANGO-algorithmic_trading/futures_trader/tasks.py", line 111, in auto_trader_per_symbol
    FuturesBotTrader.create_bot(bot_data)
  File "/home/mohammad/others/codes/intellichange/DJANGO-algorithmic_trading/futures_trader/services/trader.py", line 27, in create_bot
    return bot_handler.create_bot(exchange_id=bot_data['exchange_id'],
  File "/home/mohammad/others/codes/intellichange/DJANGO-algorithmic_trading/futures_trader/services/bot_handler.py", line 50, in create_bot
    if self.validate_bot_data(exchange_id, credential_id, position_data['signal']['symbol']):
  File "/home/mohammad/others/codes/intellichange/DJANGO-algorithmic_trading/futures_trader/services/bot_handler.py", line 578, in validate_bot_data
    return all([self.validate_risky_bots_limit(credential_id),
  File "/home/mohammad/others/codes/intellichange/DJANGO-algorithmic_trading/futures_trader/services/bot_handler.py", line 583, in validate_risky_bots_limit
    if not self.get_number_of_risky_bots(credential_id) < max_number_of_risky_bots:
  File "/home/mohammad/others/codes/intellichange/DJANGO-algorithmic_trading/futures_trader/services/bot_handler.py", line 575, in get_number_of_risky_bots
    return len([bot for bot in active_bots if bot.is_risky()])
  File "/home/mohammad/others/codes/intellichange/DJANGO-algorithmic_trading/futures_trader/services/bot_handler.py", line 575, in <listcomp>
    return len([bot for bot in active_bots if bot.is_risky()])
AttributeError: 'FuturesBot' object has no attribute 'is_risky'

