ERROR 2022-04-10 18:05:49,342 retry_on_timeout 103731 140250528778048 The password (and thus its hash value) you entered is invalid (caused by CheckPasswordRequest)
Traceback (most recent call last):
  File "/home/mohammad/others/codes/intellichange/DJANGO-algorithmic_trading/futures_trader/services/external_signal_trader/auto_trader.py", line 33, in create_client
    client.sign_in(code=input('Enter code: '))
  File "/home/mohammad/others/codes/intellichange/DJANGO-algorithmic_trading/venv/lib/python3.8/site-packages/telethon/sync.py", line 39, in syncified
    return loop.run_until_complete(coro)
  File "/usr/lib/python3.8/asyncio/base_events.py", line 616, in run_until_complete
    return future.result()
  File "/home/mohammad/others/codes/intellichange/DJANGO-algorithmic_trading/venv/lib/python3.8/site-packages/telethon/client/auth.py", line 368, in sign_in
    result = await self(request)
  File "/home/mohammad/others/codes/intellichange/DJANGO-algorithmic_trading/venv/lib/python3.8/site-packages/telethon/client/users.py", line 30, in __call__
    return await self._call(self._sender, request, ordered=ordered)
  File "/home/mohammad/others/codes/intellichange/DJANGO-algorithmic_trading/venv/lib/python3.8/site-packages/telethon/client/users.py", line 84, in _call
    result = await future
telethon.errors.rpcerrorlist.SessionPasswordNeededError: Two-steps verification is enabled and a password is required (caused by SignInRequest)

During handling of the above exception, another exception occurred:

Traceback (most recent call last):
  File "/home/mohammad/others/codes/intellichange/DJANGO-algorithmic_trading/global_utils/retry_on_timeout.py", line 17, in caught_func
    _result, _error = func(*args, **kwargs), False
  File "/home/mohammad/others/codes/intellichange/DJANGO-algorithmic_trading/futures_trader/services/external_signal_trader/auto_trader.py", line 35, in create_client
    client.sign_in(password=getpass.getpass())
  File "/home/mohammad/others/codes/intellichange/DJANGO-algorithmic_trading/venv/lib/python3.8/site-packages/telethon/sync.py", line 39, in syncified
    return loop.run_until_complete(coro)
  File "/usr/lib/python3.8/asyncio/base_events.py", line 616, in run_until_complete
    return future.result()
  File "/home/mohammad/others/codes/intellichange/DJANGO-algorithmic_trading/venv/lib/python3.8/site-packages/telethon/client/auth.py", line 368, in sign_in
    result = await self(request)
  File "/home/mohammad/others/codes/intellichange/DJANGO-algorithmic_trading/venv/lib/python3.8/site-packages/telethon/client/users.py", line 30, in __call__
    return await self._call(self._sender, request, ordered=ordered)
  File "/home/mohammad/others/codes/intellichange/DJANGO-algorithmic_trading/venv/lib/python3.8/site-packages/telethon/client/users.py", line 84, in _call
    result = await future
telethon.errors.rpcerrorlist.PasswordHashInvalidError: The password (and thus its hash value) you entered is invalid (caused by CheckPasswordRequest)
