ERROR 2022-02-21 15:21:17,350 retry_on_timeout 87652 139799883319104 HTTPSConnectionPool(host='api-futures.kucoin.com', port=443): Read timed out. (read timeout=5)
Traceback (most recent call last):
  File "/home/mohammad/others/codes/intellichange/DJANGO-algorithmic_trading/venv/lib/python3.8/site-packages/urllib3/connectionpool.py", line 386, in _make_request
    self._validate_conn(conn)
  File "/home/mohammad/others/codes/intellichange/DJANGO-algorithmic_trading/venv/lib/python3.8/site-packages/urllib3/connectionpool.py", line 1040, in _validate_conn
    conn.connect()
  File "/home/mohammad/others/codes/intellichange/DJANGO-algorithmic_trading/venv/lib/python3.8/site-packages/urllib3/connection.py", line 416, in connect
    self.sock = ssl_wrap_socket(
  File "/home/mohammad/others/codes/intellichange/DJANGO-algorithmic_trading/venv/lib/python3.8/site-packages/urllib3/util/ssl_.py", line 449, in ssl_wrap_socket
    ssl_sock = _ssl_wrap_socket_impl(
  File "/home/mohammad/others/codes/intellichange/DJANGO-algorithmic_trading/venv/lib/python3.8/site-packages/urllib3/util/ssl_.py", line 493, in _ssl_wrap_socket_impl
    return ssl_context.wrap_socket(sock, server_hostname=server_hostname)
  File "/usr/lib/python3.8/ssl.py", line 500, in wrap_socket
    return self.sslsocket_class._create(
  File "/usr/lib/python3.8/ssl.py", line 1040, in _create
    self.do_handshake()
  File "/usr/lib/python3.8/ssl.py", line 1309, in do_handshake
    self._sslobj.do_handshake()
socket.timeout: _ssl.c:1114: The handshake operation timed out

During handling of the above exception, another exception occurred:

Traceback (most recent call last):
  File "/home/mohammad/others/codes/intellichange/DJANGO-algorithmic_trading/venv/lib/python3.8/site-packages/requests/adapters.py", line 439, in send
    resp = conn.urlopen(
  File "/home/mohammad/others/codes/intellichange/DJANGO-algorithmic_trading/venv/lib/python3.8/site-packages/urllib3/connectionpool.py", line 785, in urlopen
    retries = retries.increment(
  File "/home/mohammad/others/codes/intellichange/DJANGO-algorithmic_trading/venv/lib/python3.8/site-packages/urllib3/util/retry.py", line 550, in increment
    raise six.reraise(type(error), error, _stacktrace)
  File "/home/mohammad/others/codes/intellichange/DJANGO-algorithmic_trading/venv/lib/python3.8/site-packages/urllib3/packages/six.py", line 770, in reraise
    raise value
  File "/home/mohammad/others/codes/intellichange/DJANGO-algorithmic_trading/venv/lib/python3.8/site-packages/urllib3/connectionpool.py", line 703, in urlopen
    httplib_response = self._make_request(
  File "/home/mohammad/others/codes/intellichange/DJANGO-algorithmic_trading/venv/lib/python3.8/site-packages/urllib3/connectionpool.py", line 389, in _make_request
    self._raise_timeout(err=e, url=url, timeout_value=conn.timeout)
  File "/home/mohammad/others/codes/intellichange/DJANGO-algorithmic_trading/venv/lib/python3.8/site-packages/urllib3/connectionpool.py", line 340, in _raise_timeout
    raise ReadTimeoutError(
urllib3.exceptions.ReadTimeoutError: HTTPSConnectionPool(host='api-futures.kucoin.com', port=443): Read timed out. (read timeout=5)

During handling of the above exception, another exception occurred:

Traceback (most recent call last):
  File "/home/mohammad/others/codes/intellichange/DJANGO-algorithmic_trading/global_utils/retry_on_timeout.py", line 17, in caught_func
    _result, _error = func(*args, **kwargs), False
  File "/home/mohammad/others/codes/intellichange/DJANGO-algorithmic_trading/futures_trader/exchange/exchange.py", line 56, in get_all_positions
    return self._sdk_exchange.trade_client.get_all_position()
  File "/home/mohammad/others/codes/intellichange/DJANGO-algorithmic_trading/venv/lib/python3.8/site-packages/kucoin_futures/trade/trade.py", line 157, in get_all_position
    return self._request('GET', '/api/v1/positions')
  File "/home/mohammad/others/codes/intellichange/DJANGO-algorithmic_trading/venv/lib/python3.8/site-packages/kucoin_futures/base_request/base_request.py", line 87, in _request
    response_data = requests.request(method, url, headers=headers, timeout=timeout)
  File "/home/mohammad/others/codes/intellichange/DJANGO-algorithmic_trading/venv/lib/python3.8/site-packages/requests/api.py", line 61, in request
    return session.request(method=method, url=url, **kwargs)
  File "/home/mohammad/others/codes/intellichange/DJANGO-algorithmic_trading/venv/lib/python3.8/site-packages/requests/sessions.py", line 542, in request
    resp = self.send(prep, **send_kwargs)
  File "/home/mohammad/others/codes/intellichange/DJANGO-algorithmic_trading/venv/lib/python3.8/site-packages/requests/sessions.py", line 655, in send
    r = adapter.send(request, **kwargs)
  File "/home/mohammad/others/codes/intellichange/DJANGO-algorithmic_trading/venv/lib/python3.8/site-packages/requests/adapters.py", line 529, in send
    raise ReadTimeout(e, request=request)
requests.exceptions.ReadTimeout: HTTPSConnectionPool(host='api-futures.kucoin.com', port=443): Read timed out. (read timeout=5)
ERROR 2022-02-21 15:22:24,122 bot_handler 87652 139799084525312 Creating bot failed because position with symbol BTC/USDT is duplicate!
ERROR 2022-02-21 15:22:37,180 bot_handler 87652 139799084525312 Creating bot failed because position with symbol BTC/USDT is duplicate!
ERROR 2022-02-21 15:22:49,198 bot_handler 87652 139799084525312 Creating bot failed because position with symbol BTC/USDT is duplicate!
ERROR 2022-02-21 15:23:02,211 bot_handler 87652 139799084525312 Creating bot failed because position with symbol BTC/USDT is duplicate!
ERROR 2022-02-21 15:23:15,233 bot_handler 87652 139799084525312 Creating bot failed because position with symbol BTC/USDT is duplicate!
ERROR 2022-02-21 15:23:44,267 bot_handler 87652 139799084525312 Creating bot failed because position with symbol BTC/USDT is duplicate!
ERROR 2022-02-21 15:23:57,285 bot_handler 87652 139799084525312 Creating bot failed because position with symbol BTC/USDT is duplicate!
ERROR 2022-02-21 15:24:12,304 bot_handler 87652 139799084525312 Creating bot failed because position with symbol BTC/USDT is duplicate!
ERROR 2022-02-21 15:24:24,333 bot_handler 87652 139799084525312 Creating bot failed because position with symbol BTC/USDT is duplicate!
